Workbook

Sheet DCF
B2: PIDILITE INDUSTRIES — DCF VALUATION
B4: Enterprise-value DCF | INR crore except per-share data
B6: FORECAST FCFF
B8: Fiscal Year | F8: FY22 | G8: FY23 | H8: FY24 | I8: FY25 | J8: FY26 | K8: FY27 | L8: FY28 | M8: FY29 | N8: FY30 | O8: FY31 | P8: FY32 | Q8: FY33 | R8: FY34 | S8: FY35 | T8: FY36
B20: Revenue | F20: ='RAW FS'!C7 -> 8917 | G20: ='RAW FS'!D7 -> 10660 | H20: ='RAW FS'!E7 -> 11333 | I20: ='RAW FS'!F7 -> 13140.31 | J20: ='RAW FS'!G7 -> 14600.83 | K20: =J20*(1+K21) -> 16206.921 | L20: =K20*(1+L21) -> 17989.683 | M20: =L20*(1+M21) -> 19878.599 | N20: =M20*(1+N21) -> 21866.459 | O20: =N20*(1+O21) -> 23943.773 | P20: =O20*(1+P21) -> 26098.712 | Q20: =P20*(1+Q21) -> 28186.609 | R20: =Q20*(1+R21) -> 30159.672 | ... T20: =S20*(1+T21) -> 34047.254
B21: Revenue Growth | G21: =G20/F20-1 -> 0.19546933 | H21: =H20/G20-1 -> 0.063133208 | I21: =I20/H20-1 -> 0.15947322 | J21: =J20/I20-1 -> 0.11114806 | K21: ='Data Sheet'!H30 -> 0.11 | L21: ='Data Sheet'!I30 -> 0.11 | M21: ='Data Sheet'!J30 -> 0.105 | N21: ='Data Sheet'!K30 -> 0.1 | O21: ='Data Sheet'!L30 -> 0.095 | P21: ='Data Sheet'!M30 -> 0.09 | Q21: ='Data Sheet'!N30 -> 0.08 | R21: ='Data Sheet'!O30 -> 0.07 | ... T21: ='Data Sheet'!Q30 -> 0.06
V22: Chart data
B23: EBITDA | F23: ='RAW FS'!C8 -> 2020 | G23: ='RAW FS'!D8 -> 2165 | H23: ='RAW FS'!E8 -> 3057 | I23: ='RAW FS'!F8 -> 3590 | J23: ='RAW FS'!G8 -> 4163.81 | K23: =K20*K24 -> 4456.9034 | L23: =L20*L24 -> 4929.173 | M23: =M20*M24 -> 5406.979 | N23: =N20*N24 -> 5903.944 | O23: =O20*O24 -> 6416.9311 | P23: =P20*P24 -> 6942.2575 | Q23: =Q20*Q24 -> 7441.2649 | R23: =R20*R24 -> 7901.8341 | ... T23: =T20*T24 -> 8852.286
B24: EBITDA Margin | F24: =F23/F20 -> 0.22653359 | G24: =G23/G20 -> 0.20309568 | H24: =H23/H20 -> 0.26974323 | I24: =I23/I20 -> 0.27320512 | J24: =J23/J20 -> 0.28517625 | K24: ='Data Sheet'!H31 -> 0.275 | L24: ='Data Sheet'!I31 -> 0.274 | M24: ='Data Sheet'!J31 -> 0.272 | N24: ='Data Sheet'!K31 -> 0.27 | O24: ='Data Sheet'!L31 -> 0.268 | P24: ='Data Sheet'!M31 -> 0.266 | Q24: ='Data Sheet'!N31 -> 0.264 | R24: ='Data Sheet'!O31 -> 0.262 | ... T24: ='Data Sheet'!Q31 -> 0.26 | V24: FY | W24: Revenue | X24: EBITDA
V25: FY22 | W25: =F20 -> 8917 | X25: =F23 -> 2020
B26: D&A | F26: ='RAW FS'!C9 -> 194 | G26: ='RAW FS'!D9 -> 222 | H26: ='RAW FS'!E9 -> 289 | I26: ='RAW FS'!F9 -> 358.48 | J26: ='RAW FS'!G9 -> 394.71 | K26: =K20*'Data Sheet'!H32 -> 437.58688 | L26: =L20*'Data Sheet'!I32 -> 485.72143 | M26: =M20*'Data Sheet'!J32 -> 536.72218 | N26: =N20*'Data Sheet'!K32 -> 590.3944 | O26: =O20*'Data Sheet'!L32 -> 646.48187 | P26: =P20*'Data Sheet'!M32 -> 704.66524 | Q26: =Q20*'Data Sheet'!N32 -> 761.03845 | R26: =R20*'Data Sheet'!O32 -> 814.31115 | ... T26: =T20*'Data Sheet'!Q32 -> 919.27585 | V26: FY23 | W26: =G20 -> 10660 | X26: =G23 -> 2165
B27: EBIT | F27: =F23-F26 -> 1826 | G27: =G23-G26 -> 1943 | H27: =H23-H26 -> 2768 | I27: =I23-I26 -> 3231.52 | J27: =J23-J26 -> 3769.1 | K27: =K23-K26 -> 4019.3165 | L27: =L23-L26 -> 4443.4516 | M27: =M23-M26 -> 4870.2568 | ... T27: =T23-T26 -> 7933.0101 | V27: FY24 | W27: =H20 -> 11333 | X27: =H23 -> 3057
V28: FY25 | W28: =I20 -> 13140.31 | X28: =I23 -> 3590
B29: Tax Rate | F29: =('RAW FS'!C11-'RAW FS'!C12)/'RAW FS'!C11 -> 0.24820574 | G29: =('RAW FS'!D11-'RAW FS'!D12)/'RAW FS'!D11 -> 0.26601387 | H29: =('RAW FS'!E11-'RAW FS'!E12)/'RAW FS'!E11 -> 0.14616293 | I29: =('RAW FS'!F11-'RAW FS'!F12)/'RAW FS'!F11 -> 0.26444893 | J29: =('RAW FS'!G11-'RAW FS'!G12)/'RAW FS'!G11 -> 0.26241126 | K29: ='Data Sheet'!H35 -> 0.255 | L29: ='Data Sheet'!I35 -> 0.255 | M29: ='Data Sheet'!J35 -> 0.255 | N29: ='Data Sheet'!K35 -> 0.255 | O29: ='Data Sheet'!L35 -> 0.255 | P29: ='Data Sheet'!M35 -> 0.255 | Q29: ='Data Sheet'!N35 -> 0.255 | R29: ='Data Sheet'!O35 -> 0.255 | ... T29: ='Data Sheet'!Q35 -> 0.255 | V29: FY26 | W29: =J20 -> 14600.83 | X29: =J23 -> 4163.81
B30: NOPAT | F30: =F27*(1-F29) -> 1372.7763 | G30: =G27*(1-G29) -> 1426.135 | H30: =H27*(1-H29) -> 2363.421 | I30: =I27*(1-I29) -> 2376.948 | J30: =J27*(1-J29) -> 2780.0457 | K30: =K27*(1-K29) -> 2994.3908 | L30: =L27*(1-L29) -> 3310.3715 | M30: =M27*(1-M29) -> 3628.3413 | ... T30: =T27*(1-T29) -> 5910.0926 | V30: FY27 | W30: =K20 -> 16206.921 | X30: =K23 -> 4456.9034
V31: FY28 | W31: =L20 -> 17989.683 | X31: =L23 -> 4929.173
B32: Capex | F32: ='RAW FS'!C13 -> 374.7 | G32: ='RAW FS'!D13 -> 505.4 | H32: ='RAW FS'!E13 -> 558.7 | I32: ='RAW FS'!F13 -> 452.34 | J32: ='RAW FS'!G13 -> 592.77 | K32: =K20*'Data Sheet'!H33 -> 648.27685 | L32: =L20*'Data Sheet'!I33 -> 719.58731 | M32: =M20*'Data Sheet'!J33 -> 795.14397 | N32: =N20*'Data Sheet'!K33 -> 874.65837 | O32: =O20*'Data Sheet'!L33 -> 957.75092 | P32: =P20*'Data Sheet'!M33 -> 1043.9485 | Q32: =Q20*'Data Sheet'!N33 -> 1127.4644 | R32: =R20*'Data Sheet'!O33 -> 1206.3869 | ... T32: =T20*'Data Sheet'!Q33 -> 1361.8902 | V32: FY29 | W32: =M20 -> 19878.599 | X32: =M23 -> 5406.979
V33: FY30 | W33: =N20 -> 21866.459 | X33: =N23 -> 5903.944
B34: Operating NWC | F34: ='RAW FS'!C19 -> 1490.2 | G34: ='RAW FS'!D19 -> 1491.29 | H34: ='RAW FS'!E19 -> 962.69 | I34: ='RAW FS'!F19 -> 1070.79 | J34: ='RAW FS'!G19 -> 1091.31 | K34: =K20*'Data Sheet'!H34 -> 1296.5537 | L34: =L20*'Data Sheet'!I34 -> 1439.1746 | M34: =M20*'Data Sheet'!J34 -> 1590.2879 | N34: =N20*'Data Sheet'!K34 -> 1749.3167 | O34: =O20*'Data Sheet'!L34 -> 1915.5018 | P34: =P20*'Data Sheet'!M34 -> 2087.897 | Q34: =Q20*'Data Sheet'!N34 -> 2254.9288 | R34: =R20*'Data Sheet'!O34 -> 2412.7738 | ... T34: =T20*'Data Sheet'!Q34 -> 2723.7803 | V34: FY31 | W34: =O20 -> 23943.773 | X34: =O23 -> 6416.9311
B35: Change in NWC | G35: =G34-F34 -> 1.09 | H35: =H34-G34 -> -528.6 | I35: =I34-H34 -> 108.1 | J35: =J34-I34 -> 20.52 | K35: =K34-J34 -> 205.2437 | L35: =L34-K34 -> 142.62091 | M35: =M34-L34 -> 151.11333 | N35: =N34-M34 -> 159.02879 | ... T35: =T34-S34 -> 154.17624 | V35: FY32 | W35: =P20 -> 26098.712 | X35: =P23 -> 6942.2575
V36: FY33 | W36: =Q20 -> 28186.609 | X36: =Q23 -> 7441.2649
B37: FCFF | K37: =K30+K26-K32-K35 -> 2578.4571 | L37: =L30+L26-L32-L35 -> 2933.8847 | M37: =M30+M26-M32-M35 -> 3218.8062 | N37: =N30+N26-N32-N35 -> 3515.3017 | O37: =O30+O26-O32-O35 -> 3821.5306 | P37: =P30+P26-P32-P35 -> 4135.3278 | Q37: =Q30+Q26-Q32-Q35 -> 4443.311 | R37: =R30+R26-R32-R35 -> 4730.2838 | ... T37: =T30+T26-T32-T35 -> 5313.302 | V37: FY34 | W37: =R20 -> 30159.672 | X37: =R23 -> 7901.8341
B38: Discount Factor | K38: =1/(1+$N$44)^0.5 -> 0.9426808 | L38: =1/(1+$N$44)^1.5 -> 0.83771055 | M38: =1/(1+$N$44)^2.5 -> 0.74442905 | N38: =1/(1+$N$44)^3.5 -> 0.66153471 | O38: =1/(1+$N$44)^4.5 -> 0.58787089 | P38: =1/(1+$N$44)^5.5 -> 0.52240976 | Q38: =1/(1+$N$44)^6.5 -> 0.46423791 | R38: =1/(1+$N$44)^7.5 -> 0.41254367 | S38: =1/(1+$N$44)^8.5 -> 0.36660573 | T38: =1/(1+$N$44)^9.5 -> 0.32578312 | V38: FY35 | W38: =S20 -> 32120.051 | X38: =S23 -> 8383.3333
B39: PV of FCFF | K39: =K37*K38 -> 2430.662 | L39: =L37*L38 -> 2457.7461 | M39: =M37*M38 -> 2396.1728 | N39: =N37*N38 -> 2325.4941 | O39: =O37*O38 -> 2246.5666 | P39: =P37*P38 -> 2160.3356 | Q39: =Q37*Q38 -> 2062.7534 | R39: =R37*R38 -> 1951.4487 | ... T39: =T37*T38 -> 1730.9841 | V39: FY36 | W39: =T20 -> 34047.254 | X39: =T23 -> 8852.286
B42: VALUATION OUTPUT
B44: WACC | N44: =WACC!D39 -> 0.12530611
B45: Terminal Growth Rate | N45: ='Data Sheet'!C39 -> 0.055
B46: PV of Explicit FCFF | N46: =SUM(K39:T39) -> 21604.393
B47: Terminal Year FCFF | N47: =T37 -> 5313.302
B48: Terminal Value | N48: =N47*(1+N45)/(N44-N45) -> 79730.394
B49: PV of Terminal Value | N49: =N48*T38 -> 25974.816
B50: Enterprise Value | N50: =N46+N49 -> 47579.209
B51: Add: Cash & Current Investments | N51: ='Data Sheet'!C13+'Data Sheet'!C14 -> 4218.73
B52: Less: Debt | N52: ='Data Sheet'!C12 -> 105.91
B53: Equity Value | N53: =N50+N51-N52 -> 51692.029
B54: Shares Outstanding (mn) | N54: ='Data Sheet'!C9 -> 1018.0492
B55: Implied Value / Share (₹) | N55: =N53/N54*10 -> 507.75571
B56: Current Share Price (₹) | N56: ='Data Sheet'!C8 -> 1517.2
B57: Implied Upside / (Downside) | N57: =N55/N56-1 -> -0.6653337
B58: EV/EBITDA-Implied Value/Share (₹) | N58: =Comps!D35 -> 1149.9118
...

Sheet RAW FS
B2: PIDILITE INDUSTRIES — RAW FINANCIALS
B4: All figures in INR crore unless stated otherwise
B6: Particulars | C6: FY22 | D6: FY23 | E6: FY24 | F6: FY25 | G6: FY26
B7: Revenue from Operations | C7: 8917 | D7: 10660 | E7: 11333 | F7: 13140.31 | G7: 14600.83
B8: EBITDA | C8: 2020 | D8: 2165 | E8: 3057 | F8: 3590 | G8: 4163.81
B9: Depreciation & Amortisation | C9: 194 | D9: 222 | E9: 289 | F9: 358.48 | G9: 394.71
B10: EBIT | C10: 1826 | D10: 1943 | E10: 2768 | F10: 3231.52 | G10: 3769.1
B11: Profit Before Tax | C11: 1672 | D11: 2451 | E11: 2455 | F11: 2822.7 | G11: 3320.17
B12: Profit After Tax | C12: 1257 | D12: 1799 | E12: 2096.17 | F12: 2076.24 | G12: 2448.92
B13: Capital Expenditure | C13: 374.7 | D13: 505.4 | E13: 558.7 | F13: 452.34 | G13: 592.77
B14: Inventories | C14: 1695.09 | D14: 1817.08 | E14: 1414.9 | F14: 1685.09 | G14: 1737.6
B15: Trade Receivables | C15: 1430.54 | D15: 1535.27 | E15: 1674.69 | F15: 1811.15 | G15: 2181.1
B16: Other Operating Current Assets | C16: 361.29 | D16: 351.32 | E16: 343.37 | F16: 467.58 | G16: 394.45
B17: Trade Payables | C17: 1049.29 | D17: 1063.59 | E17: 1147.6 | F17: 1390.05 | G17: 1536.63
B18: Other Operating Current Liabilities | C18: 947.43 | D18: 1148.79 | E18: 1322.67 | F18: 1502.98 | G18: 1685.21
... B23: Equity Attributable to Owners | C23: 6403.71 | D23: 7212.28 | E23: 8407.16 | F23: 9754.46 | G23: 10832.17
B24: Revenue Growth | D24: =D7/C7-1 -> 0.19546933 | E24: =E7/D7-1 -> 0.063133208 | F24: =F7/E7-1 -> 0.15947322 | G24: =G7/F7-1 -> 0.11114806
B25: EBITDA Margin | C25: =C8/C7 -> 0.22653359 | D25: =D8/D7 -> 0.20309568 | E25: =E8/E7 -> 0.26974323 | F25: =F8/F7 -> 0.27320512 | G25: =G8/G7 -> 0.28517625
B26: EBIT Margin | C26: =C10/C7 -> 0.20477739 | D26: =D10/D7 -> 0.18227017 | E26: =E10/E7 -> 0.24424248 | F26: =F10/F7 -> 0.24592418 | G26: =G10/G7 -> 0.25814286
B27: NWC % Revenue | C27: =C19/C7 -> 0.16711899 | D27: =D19/D7 -> 0.13989587 | E27: =E19/E7 -> 0.084945734 | F27: =F19/F7 -> 0.081488945 | G27: =G19/G7 -> 0.074743011
B29: Source / methodology
B30: Historical figures are based primarily on Pidilite annual reports / audited results and public financial databases. FY26 consolidated revenue, PBT, PAT and D&A are from FY26 audited results; balance-sheet and cash-flow series are cross-checked against public financial databases. Consolidated figures are used for the enterprise-value DCF.

Sheet Data Sheet
B2: PIDILITE INDUSTRIES — DATA SHEET
B4: Market data, historical operating metrics and key DCF inputs
B6: MARKET DATA
B7: Company Name | C7: PIDILITE INDUSTRIES LTD
B8: Current Share Price (₹) | C8: 1517.2
B9: Shares Outstanding (mn) | C9: 1018.0492
B10: Market Capitalization (₹ Cr) | C10: =C8*C9/10 -> 154458.43
B11: Face Value (₹) | C11: 1
B12: Total Debt (₹ Cr) | C12: 105.91
B13: Cash & Cash Equivalents (₹ Cr) | C13: 298.9
B14: Current Investments (₹ Cr) | C14: 3919.83
B15: Net Debt / (Cash) (₹ Cr) | C15: =C12-C13-C14 -> -4112.82
B18: HISTORICAL / FORECAST DRIVER SUMMARY
B19: Metric | C19: FY22 | D19: FY23 | E19: FY24 | F19: FY25 | G19: FY26 | H19: FY27E | I19: FY28E | J19: FY29E | K19: FY30E | L19: FY31E
B20: Revenue | C20: ='RAW FS'!C7 -> 8917 | D20: ='RAW FS'!D7 -> 10660 | E20: ='RAW FS'!E7 -> 11333 | F20: ='RAW FS'!F7 -> 13140.31 | G20: ='RAW FS'!G7 -> 14600.83
B21: Revenue Growth | D21: =D20/C20-1 -> 0.19546933 | E21: =E20/D20-1 -> 0.063133208 | F21: =F20/E20-1 -> 0.15947322 | G21: =G20/F20-1 -> 0.11114806
B22: EBITDA | C22: ='RAW FS'!C8 -> 2020 | D22: ='RAW FS'!D8 -> 2165 | E22: ='RAW FS'!E8 -> 3057 | F22: ='RAW FS'!F8 -> 3590 | G22: ='RAW FS'!G8 -> 4163.81
B23: EBITDA Margin | C23: =C22/C20 -> 0.22653359 | D23: =D22/D20 -> 0.20309568 | E23: =E22/E20 -> 0.26974323 | F23: =F22/F20 -> 0.27320512 | G23: =G22/G20 -> 0.28517625
B24: D&A | C24: ='RAW FS'!C9 -> 194 | D24: ='RAW FS'!D9 -> 222 | E24: ='RAW FS'!E9 -> 289 | F24: ='RAW FS'!F9 -> 358.48 | G24: ='RAW FS'!G9 -> 394.71
B25: Capex | C25: ='RAW FS'!C13 -> 374.7 | D25: ='RAW FS'!D13 -> 505.4 | E25: ='RAW FS'!E13 -> 558.7 | F25: ='RAW FS'!F13 -> 452.34 | G25: ='RAW FS'!G13 -> 592.77
B26: NWC | C26: ='RAW FS'!C19 -> 1490.2 | D26: ='RAW FS'!D19 -> 1491.29 | E26: ='RAW FS'!E19 -> 962.69 | F26: ='RAW FS'!F19 -> 1070.79 | G26: ='RAW FS'!G19 -> 1091.31
B27: NWC % Revenue | C27: =C26/C20 -> 0.16711899 | D27: =D26/D20 -> 0.13989587 | E27: =E26/E20 -> 0.084945734 | F27: =F26/F20 -> 0.081488945 | G27: =G26/G20 -> 0.074743011
H29: FY27E | I29: FY28E | J29: FY29E | K29: FY30E | L29: FY31E | M29: FY32E | N29: FY33E | O29: FY34E | P29: FY35E | Q29: FY36E
B30: Revenue Growth | H30: 0.11 | I30: 0.11 | J30: 0.105 | K30: 0.1 | L30: 0.095 | M30: 0.09 | N30: 0.08 | O30: 0.07 | P30: 0.065 | Q30: 0.06
B31: EBITDA Margin | H31: 0.275 | I31: 0.274 | J31: 0.272 | K31: 0.27 | L31: 0.268 | M31: 0.266 | N31: 0.264 | O31: 0.262 | P31: 0.261 | Q31: 0.26
B32: D&A % Revenue | H32: 0.027 | I32: 0.027 | J32: 0.027 | K32: 0.027 | L32: 0.027 | M32: 0.027 | N32: 0.027 | O32: 0.027 | P32: 0.027 | Q32: 0.027
B33: Capex % Revenue | H33: 0.04 | I33: 0.04 | J33: 0.04 | K33: 0.04 | L33: 0.04 | M33: 0.04 | N33: 0.04 | O33: 0.04 | P33: 0.04 | Q33: 0.04
B34: NWC % Revenue | H34: 0.08 | I34: 0.08 | J34: 0.08 | K34: 0.08 | L34: 0.08 | M34: 0.08 | N34: 0.08 | O34: 0.08 | P34: 0.08 | Q34: 0.08
B35: Tax Rate | H35: 0.255 | I35: 0.255 | J35: 0.255 | K35: 0.255 | L35: 0.255 | M35: 0.255 | N35: 0.255 | O35: 0.255 | P35: 0.255 | Q35: 0.255
B38: WACC | C38: =WACC!D39 -> 0.12530611
B39: Terminal Growth Rate | C39: 0.055
B40: DCF Valuation Date | C40: 46290

Sheet WACC
B2: PIDILITE INDUSTRIES — WACC
B4: Cost of capital using CAPM + peer beta triangulation
B6: PEER COMPARABLES
B8: Company | C8: Country | D8: Debt (₹ Cr) | E8: Equity Value (₹ Cr) | F8: Tax Rate | G8: D/E | H8: Levered Beta | I8: Unlevered Beta | J8: Source / Note
B9: Asian Paints | C9: India | D9: 2290.29 | E9: =Asian!C47*95.77 -> 229148.88 | F9: 0.3 | G9: =D9/E9 -> 0.0099947685 | H9: =Asian!C15 -> 1.1324446 | I9: =H9/(1+(1-F9)*G9) -> 1.1245767 | J9: Mkt cap = Sep-2026 close (Yahoo Finance, Asian tab) x 95.77 Cr shares; refresh before use
B10: Berger Paints | C10: India | D10: 670.27 | E10: =Berger!C47*116.57 -> 52386.558 | F10: 0.3 | G10: =D10/E10 -> 0.012794694 | H10: =Berger!C15 -> 1.1393464 | I10: =H10/(1+(1-F10)*G10) -> 1.1292327 | J10: Mkt cap = Sep-2026 close (Yahoo Finance, Berger tab) x 116.57 Cr shares; refresh before use
B11: Kansai Nerolac | C11: India | D11: 296.39 | E11: =Kansai!C47*80.71 -> 14480.181 | F11: 0.3 | G11: =D11/E11 -> 0.020468667 | H11: =Kansai!C15 -> 1.1567668 | I11: =H11/(1+(1-F11)*G11) -> 1.1404267 | J11: Mkt cap = Sep-2026 close (Yahoo Finance, Kansai tab) x 80.71 Cr shares; refresh before use
B12: Astral | C12: India | D12: 1050 | E12: =Astral!C47*26.9 -> 37444.8 | F12: 0.25 | G12: =D12/E12 -> 0.028041277 | H12: =Astral!C15 -> 0.58280014 | I12: =H12/(1+(1-F12)*G12) -> 0.57079576 | J12: Mkt cap = Sep-2026 close (Yahoo Finance, Astral tab) x 26.9 Cr shares; refresh before use
B13: Supreme Industries | C13: India | D13: 130 | E13: =Supreme!C47*12.7 -> 43611.8 | F13: 0.25 | G13: =D13/E13 -> 0.0029808446 | H13: =Supreme!C15 -> 0.56361033 | I13: =H13/(1+(1-F13)*G13) -> 0.56235312 | J13: Mkt cap = Sep-2026 close (Yahoo Finance, Supreme tab) x 12.7 Cr shares; refresh before use
B15: Median Unlevered Beta | I15: =MEDIAN(I9:I13) -> 1.1245767
B16: Average Unlevered Beta | I16: =AVERAGE(I9:I13) -> 0.90547701
B17: Paints-Only Median Unlevered Beta (Asian, Berger, Kansai) | I17: =MEDIAN(I9:I11) -> 1.1292327
B18: Beta Selection Switch (1 = Median, 2 = Average, 3 = Paints-only) | I18: 2
B19: COST OF EQUITY
B21: Risk-Free Rate | D21: 0.0712
B22: Equity Risk Premium | D22: 0.06
B23: Target Debt / Equity | D23: 0.01
B24: Marginal Tax Rate | D24: 0.255
B25: Selected Unlevered Beta | D25: =CHOOSE($I$18,I15,I16,I17) -> 0.90547701
B26: Relevered Beta | D26: =D25*(1+(1-D24)*D23) -> 0.91222281
B27: Cost of Equity | D27: =D21+D26*D22 -> 0.12593337
B30: WACC BUILD
B32: Market Capitalization | D32: ='Data Sheet'!C10 -> 154458.43
B33: Total Debt | D33: ='Data Sheet'!C12 -> 105.91
B34: Equity Weight | D34: =1/(1+D23) -> 0.99009901
B35: Debt Weight | D35: =D23/(1+D23) -> 0.0099009901
B36: Pre-Tax Cost of Debt | D36: 0.084
B37: Post-Tax Cost of Debt | D37: =D36*(1-D24) -> 0.06258
B38: Cost of Equity | D38: =D27 -> 0.12593337
B39: Weighted Average Cost of Capital | D39: =D34*D38+D35*D37 -> 0.12530611
B42: Notes
B43: Risk-free rate uses the India 10-year government bond yield around 25-Sep-2026. Peer betas are 24-month regressions vs NIFTY 50 (Yahoo Finance, Adj Close), Blume-adjusted. Peer unlevering: Bu = BL / [1 + (1-T) x D/E]. Beta selection switch (I18) defaults to the full-peer AVERAGE: peers split into two clusters (paints ~1.1, pipes ~0.57 unlevered) and Pidilite sells into both decorative/DIY and construction channels, so the median (which lands on the paints cluster by a 3-vs-2 split) is less representative; 1 and 3 are shown as alternatives. ERP of 6.0% is a mid-range assumption for India (commonly cited estimates span ~5-7%); verify against the latest Damodaran India estimate and cite it. Weights use the target D/E (1%).

Sheet Comps
B2: PIDILITE INDUSTRIES — TRADING COMPS
B4: EV/EBITDA and P/E cross-check against the DCF, using listed paints & pipes peer multiples
B6: PEER TRADING MULTIPLES
B8: Company | C8: Market Cap (₹ Cr) | D8: Total Debt (₹ Cr) | E8: Cash & Investments (₹ Cr) | F8: Enterprise Value (₹ Cr) | G8: LTM EBITDA (₹ Cr) | H8: LTM PAT (₹ Cr) | I8: EPS (₹) — reference only | J8: EV/EBITDA | K8: P/E | L8: Source / Note
B9: Asian Paints | C9: =WACC!E9 -> 229148.88 | D9: =WACC!D9 -> 2290.29 | E9: 7062 | F9: =C9+D9-E9 -> 224377.17 | G9: 7240 | H9: 4837 | I9: 49.68 | J9: =F9/G9 -> 30.991322 | K9: =C9/H9 -> 47.374174 | L9: screener.in (ASIANPAINT), consolidated, TTM ended Jun-2026 for P&L; Investments as of Mar-2026 balance sheet; pulled 28-Sep-2026
B10: Berger Paints | C10: =WACC!E10 -> 52386.558 | D10: =WACC!D10 -> 670.27 | E10: 1189 | F10: =C10+D10-E10 -> 51867.828 | G10: 1912 | H10: 1218 | I10: 10.44 | J10: =F10/G10 -> 27.127525 | K10: =C10/H10 -> 43.01031 | L10: screener.in (BERGEPAINT), consolidated, TTM ended Jun-2026 for P&L; Investments as of Mar-2026 balance sheet; pulled 28-Sep-2026
B11: Kansai Nerolac | C11: =WACC!E11 -> 14480.181 | D11: =WACC!D11 -> 296.39 | E11: 2365 | F11: =C11+D11-E11 -> 12411.571 | G11: 1000 | H11: 589 | I11: 7.42 | J11: =F11/G11 -> 12.411571 | K11: =C11/H11 -> 24.584348 | L11: screener.in (KANSAINER), consolidated, TTM ended Jun-2026 for P&L; Investments as of Mar-2026 balance sheet; pulled 28-Sep-2026
B12: Astral | C12: =WACC!E12 -> 37444.8 | D12: =WACC!D12 -> 1050 | E12: 0 | F12: =C12+D12-E12 -> 38494.8 | G12: 1108 | H12: 576 | I12: 21.43 | J12: =F12/G12 -> 34.742599 | K12: =C12/H12 -> 65.008333 | L12: screener.in (ASTRAL), consolidated, TTM ended Jun-2026 for P&L; balance sheet carries no separate Investments line (cash embedded in Other Assets) as of Mar-2026; pulled 28-Sep-2026
B13: Supreme Industries | C13: =WACC!E13 -> 43611.8 | D13: =WACC!D13 -> 130 | E13: 762 | F13: =C13+D13-E13 -> 42979.8 | G13: 1632 | H13: 1032 | I13: 81.27 | J13: =F13/G13 -> 26.335662 | K13: =C13/H13 -> 42.259496 | L13: screener.in (SUPREMEIND), consolidated, TTM ended Jun-2026 for P&L; Investments as of Mar-2026 balance sheet; pulled 28-Sep-2026
B15: Median EV/EBITDA | J15: =MEDIAN(J9:J13) -> 27.127525
B16: Median P/E | K16: =MEDIAN(K9:K13) -> 43.01031
B19: APPLY MULTIPLES TO PIDILITE
B21: Pidilite FY26 Actual EBITDA (₹ Cr) | D21: ='RAW FS'!G8 -> 4163.81
B22: Pidilite FY27E Forecast EBITDA (₹ Cr) | D22: =DCF!K23 -> 4456.9034
B23: Pidilite FY26 Actual PAT (₹ Cr) | D23: ='RAW FS'!G12 -> 2448.92
B24: Shares Outstanding (mn) | D24: ='Data Sheet'!C9 -> 1018.0492
B25: Total Debt (₹ Cr) | D25: ='Data Sheet'!C12 -> 105.91
B26: Cash & Cash Equivalents (₹ Cr) | D26: ='Data Sheet'!C13 -> 298.9
B27: Current Investments (₹ Cr) | D27: ='Data Sheet'!C14 -> 3919.83
B29: IMPLIED VALUATION
B31: Implied EV — EV/EBITDA Method, FY26 Actual (₹ Cr) | D31: =$J$15*D21 -> 112953.86
B32: Implied EV — EV/EBITDA, FY27E EBITDA (LTM peer multiple x forward EBITDA; indicative) (₹ Cr) | D32: =$J$15*D22 -> 120904.76
B33: Implied Equity Value — FY26 Actual (₹ Cr) | D33: =D31+D26+D27-D25 -> 117066.68
B34: Implied Equity Value — FY27E Forecast (₹ Cr) | D34: =D32+D26+D27-D25 -> 125017.58
B35: Implied Value/Share — EV/EBITDA Method, FY26 Actual (₹) | D35: =D33/D24*10 -> 1149.9118
B36: Implied Value/Share — EV/EBITDA Method, FY27E Forecast (₹) | D36: =D34/D24*10 -> 1228.0111
B37: Implied Value/Share — P/E Method, FY26 Actual PAT (₹) | D37: =$K$16*(D23/D24*10) -> 1034.6141
B40: Note: Peer market caps (WACC!E9:E13) are refreshed to Sep-2026 closing prices x shares outstanding; peer LTM EBITDA / PAT / EPS are TTM to Jun-2026 (screener.in, 28-Sep-2026). Astral cash shown as 0 because screener carries no separate investments line - verify against the Mar-2026 balance sheet. Peer EV/EBITDA is dispersed (Kansai ~12x vs Astral ~34x), so the median is a rough anchor, not a precise target.

Sheet Intrinsic Growth
B2: PIDILITE INDUSTRIES — INTRINSIC GROWTH
B4: ROIC × Reinvestment Rate framework
B6: ROIC BUILD
B8: Metric | F8: FY22 | G8: FY23 | H8: FY24 | I8: FY25 | J8: FY26
B9: Operating Current Assets | F9: ='RAW FS'!C14+'RAW FS'!C15+'RAW FS'!C16 -> 3486.92 | G9: ='RAW FS'!D14+'RAW FS'!D15+'RAW FS'!D16 -> 3703.67 | H9: ='RAW FS'!E14+'RAW FS'!E15+'RAW FS'!E16 -> 3432.96 | I9: ='RAW FS'!F14+'RAW FS'!F15+'RAW FS'!F16 -> 3963.82 | J9: ='RAW FS'!G14+'RAW FS'!G15+'RAW FS'!G16 -> 4313.15
B10: Operating Current Liabilities | F10: ='RAW FS'!C17+'RAW FS'!C18 -> 1996.72 | G10: ='RAW FS'!D17+'RAW FS'!D18 -> 2212.38 | H10: ='RAW FS'!E17+'RAW FS'!E18 -> 2470.27 | I10: ='RAW FS'!F17+'RAW FS'!F18 -> 2893.03 | J10: ='RAW FS'!G17+'RAW FS'!G18 -> 3221.84
B11: Net Operating Working Capital | F11: =F9-F10 -> 1490.2 | G11: =G9-G10 -> 1491.29 | H11: =H9-H10 -> 962.69 | I11: =I9-I10 -> 1070.79 | J11: =J9-J10 -> 1091.31
B12: Invested Capital Proxy | F12: ='RAW FS'!C23-'RAW FS'!C20-'RAW FS'!C21 -> 5875.02 | G12: ='RAW FS'!D23-'RAW FS'!D20-'RAW FS'!D21 -> 6354.43 | H12: ='RAW FS'!E23-'RAW FS'!E20-'RAW FS'!E21 -> 6003.71 | I12: ='RAW FS'!F23-'RAW FS'!F20-'RAW FS'!F21 -> 6256.29 | J12: ='RAW FS'!G23-'RAW FS'!G20-'RAW FS'!G21 -> 6613.44
B13: EBIT | F13: ='RAW FS'!C10 -> 1826 | G13: ='RAW FS'!D10 -> 1943 | H13: ='RAW FS'!E10 -> 2768 | I13: ='RAW FS'!F10 -> 3231.52 | J13: ='RAW FS'!G10 -> 3769.1
B14: Tax Rate | F14: =('RAW FS'!C11-'RAW FS'!C12)/'RAW FS'!C11 -> 0.24820574 | G14: =('RAW FS'!D11-'RAW FS'!D12)/'RAW FS'!D11 -> 0.26601387 | H14: =('RAW FS'!E11-'RAW FS'!E12)/'RAW FS'!E11 -> 0.14616293 | I14: =('RAW FS'!F11-'RAW FS'!F12)/'RAW FS'!F11 -> 0.26444893 | J14: =('RAW FS'!G11-'RAW FS'!G12)/'RAW FS'!G11 -> 0.26241126
B15: NOPAT | F15: =F13*(1-F14) -> 1372.7763 | G15: =G13*(1-G14) -> 1426.135 | H15: =H13*(1-H14) -> 2363.421 | I15: =I13*(1-I14) -> 2376.948 | J15: =J13*(1-J14) -> 2780.0457
B16: ROIC | F16: =F15/F12 -> 0.23366326 | G16: =G15/G12 -> 0.22443162 | H16: =H15/H12 -> 0.39366009 | I16: =I15/I12 -> 0.37992932 | J16: =J15/J12 -> 0.42036304
B19: REINVESTMENT RATE & INTRINSIC GROWTH
B21: Metric | F21: FY22 | G21: FY23 | H21: FY24 | I21: FY25 | J21: FY26
B22: Capex | F22: ='RAW FS'!C13 -> 374.7 | G22: ='RAW FS'!D13 -> 505.4 | H22: ='RAW FS'!E13 -> 558.7 | I22: ='RAW FS'!F13 -> 452.34 | J22: ='RAW FS'!G13 -> 592.77 | P22: 5Y Median
B23: D&A | F23: ='RAW FS'!C9 -> 194 | G23: ='RAW FS'!D9 -> 222 | H23: ='RAW FS'!E9 -> 289 | I23: ='RAW FS'!F9 -> 358.48 | J23: ='RAW FS'!G9 -> 394.71 | P23: =MEDIAN(F28:J28) -> 0.032281112
B24: Change in NWC | F24: 0 | G24: =G11-F11 -> 1.09 | H24: =H11-G11 -> -528.6 | I24: =I11-H11 -> 108.1 | J24: =J11-I11 -> 20.52 | P24: 5Y Average
B25: Reinvestment | F25: =F22-F23+F24 -> 180.7 | G25: =G22-G23+G24 -> 284.49 | H25: =H22-H23+H24 -> -258.9 | I25: =I22-I23+I24 -> 201.96 | J25: =J22-J23+J24 -> 218.58 | P25: =AVERAGE(F28:J28) -> 0.019547268
B26: Reinvestment Rate | F26: =F25/F15 -> 0.13163106 | G26: =G25/G15 -> 0.19948321 | H26: =H25/H15 -> -0.1095446 | I26: =I25/I15 -> 0.0849661 | J26: =J25/J15 -> 0.078624606 | P26: Terminal g
B27: ROIC | F27: =F16 -> 0.23366326 | G27: =G16 -> 0.22443162 | H27: =H16 -> 0.39366009 | I27: =I16 -> 0.37992932 | J27: =J16 -> 0.42036304 | P27: ='Data Sheet'!C39 -> 0.055
B28: Intrinsic Growth | F28: =F26*F27 -> 0.030757342 | G28: =G26*G27 -> 0.044770341 | H28: =H26*H27 -> -0.043123335 | I28: =I26*I27 -> 0.032281112 | J28: =J26*J27 -> 0.033050878

Sheet Astral
B2: ASTRAL LTD — BETA SUPPORT
B4: Peer beta input sheet | refresh market series before interview use
B6: BETA INPUT / TRIANGULATION
B8: Company | C8: ASTRAL LTD
B9: Reference Levered Beta | C9: =J23 -> 0.44373352
B10: Method | C10: 2-year monthly regression beta vs NIFTY 50 (Oct-2024 to Sep-2026), Adj Close, Source: Yahoo Finance
B12: Raw Beta Weight | C12: 0.75
B13: Market Beta | C13: 1
B14: Market Beta Weight | C14: =1-C12 -> 0.25
B15: Adjusted Beta | C15: =C9*C12+C13*C14 -> 0.58280014
B18: Beta regression completed using 24 months of Adj Close data (Oct-2024 to Sep-2026) for the peer and NIFTY 50, sourced from Yahoo Finance. Regression Beta (J23) feeds directly into Reference Levered Beta (C9) above, which is then Blume-adjusted (rows 12-15) before use in the WACC build.
B23: Date | C23: Peer Price (Adj Close) | D23: Peer Return | E23: NIFTY Price (Adj Close) | F23: NIFTY Return | I23: Regression Beta | J23: =IFERROR(SLOPE(D25:D47,F25:F47),"") -> 0.44373352
B24: 45566 | C24: 1761.28 | E24: 24205.35
B25: 45597 | C25: 1782.87 | D25: =IFERROR(C25/C24-1,"") -> 0.01225813 | E25: 24131.1 | F25: =IFERROR(E25/E24-1,"") -> -0.0030675037
B26: 45627 | C26: 1645.21 | D26: =IFERROR(C26/C25-1,"") -> -0.077212584 | E26: 23644.8 | F26: =IFERROR(E26/E25-1,"") -> -0.020152417
B27: 45658 | C27: 1500.88 | D27: =IFERROR(C27/C26-1,"") -> -0.087727403 | E27: 23508.4 | F27: =IFERROR(E27/E26-1,"") -> -0.0057687102
B28: 45689 | C28: 1331.55 | D28: =IFERROR(C28/C27-1,"") -> -0.11282048 | E28: 22124.7 | F28: =IFERROR(E28/E27-1,"") -> -0.058859812
B29: 45717 | C29: 1288.73 | D29: =IFERROR(C29/C28-1,"") -> -0.032158011 | E29: 23519.35 | F29: =IFERROR(E29/E28-1,"") -> 0.063035883
B30: 45748 | C30: 1339.37 | D30: =IFERROR(C30/C29-1,"") -> 0.039294499 | E30: 24334.2 | F30: =IFERROR(E30/E29-1,"") -> 0.03464594
B31: 45778 | C31: 1491.71 | D31: =IFERROR(C31/C30-1,"") -> 0.11374004 | E31: 24750.7 | F31: =IFERROR(E31/E30-1,"") -> 0.017115829
B32: 45809 | C32: 1500.38 | D32: =IFERROR(C32/C31-1,"") -> 0.0058121217 | E32: 25517.05 | F32: =IFERROR(E32/E31-1,"") -> 0.030962761
B33: 45839 | C33: 1395.23 | D33: =IFERROR(C33/C32-1,"") -> -0.070082246 | E33: 24768.35 | F33: =IFERROR(E33/E32-1,"") -> -0.029341166
B34: 45870 | C34: 1356.37 | D34: =IFERROR(C34/C33-1,"") -> -0.027852039 | E34: 24426.85 | F34: =IFERROR(E34/E33-1,"") -> -0.013787757
B35: 45901 | C35: 1362.95 | D35: =IFERROR(C35/C34-1,"") -> 0.0048511837 | E35: 24611.1 | F35: =IFERROR(E35/E34-1,"") -> 0.0075429292
B36: 45931 | C36: 1446.44 | D36: =IFERROR(C36/C35-1,"") -> 0.061256833 | E36: 25722.1 | F36: =IFERROR(E36/E35-1,"") -> 0.045142233
... B47: 46266 | C47: 1392 | D47: =IFERROR(C47/C46-1,"") -> -0.085534095 | E47: 23063.1 | F47: =IFERROR(E47/E46-1,"") -> -0.042245976

Sheet Supreme
B2: SUPREME INDUSTRIES LTD — BETA SUPPORT
B4: Peer beta input sheet | refresh market series before interview use
B6: BETA INPUT / TRIANGULATION
B8: Company | C8: SUPREME INDUSTRIES LTD
B9: Reference Levered Beta | C9: =J23 -> 0.41814711
B10: Method | C10: 2-year monthly regression beta vs NIFTY 50 (Oct-2024 to Sep-2026), Adj Close, Source: Yahoo Finance
B12: Raw Beta Weight | C12: 0.75
B13: Market Beta | C13: 1
B14: Market Beta Weight | C14: =1-C12 -> 0.25
B15: Adjusted Beta | C15: =C9*C12+C13*C14 -> 0.56361033
B18: Beta regression completed using 24 months of Adj Close data (Oct-2024 to Sep-2026) for the peer and NIFTY 50, sourced from Yahoo Finance. Regression Beta (J23) feeds directly into Reference Levered Beta (C9) above, which is then Blume-adjusted (rows 12-15) before use in the WACC build.
B23: Date | C23: Peer Price (Adj Close) | D23: Peer Return | E23: NIFTY Price (Adj Close) | F23: NIFTY Return | I23: Regression Beta | J23: =IFERROR(SLOPE(D25:D47,F25:F47),"") -> 0.41814711
B24: 45566 | C24: 4229.31 | E24: 24205.35
B25: 45597 | C25: 4580.23 | D25: =IFERROR(C25/C24-1,"") -> 0.082973346 | E25: 24131.1 | F25: =IFERROR(E25/E24-1,"") -> -0.0030675037
B26: 45627 | C26: 4628.93 | D26: =IFERROR(C26/C25-1,"") -> 0.010632654 | E26: 23644.8 | F26: =IFERROR(E26/E25-1,"") -> -0.020152417
B27: 45658 | C27: 3908.33 | D27: =IFERROR(C27/C26-1,"") -> -0.15567313 | E27: 23508.4 | F27: =IFERROR(E27/E26-1,"") -> -0.0057687102
B28: 45689 | C28: 3278.28 | D28: =IFERROR(C28/C27-1,"") -> -0.16120696 | E28: 22124.7 | F28: =IFERROR(E28/E27-1,"") -> -0.058859812
B29: 45717 | C29: 3374.04 | D29: =IFERROR(C29/C28-1,"") -> 0.02921044 | E29: 23519.35 | F29: =IFERROR(E29/E28-1,"") -> 0.063035883
B30: 45748 | C30: 3485.08 | D30: =IFERROR(C30/C29-1,"") -> 0.032910102 | E30: 24334.2 | F30: =IFERROR(E30/E29-1,"") -> 0.03464594
B31: 45778 | C31: 4083.02 | D31: =IFERROR(C31/C30-1,"") -> 0.17157138 | E31: 24750.7 | F31: =IFERROR(E31/E30-1,"") -> 0.017115829
B32: 45809 | C32: 4347.98 | D32: =IFERROR(C32/C31-1,"") -> 0.064893143 | E32: 25517.05 | F32: =IFERROR(E32/E31-1,"") -> 0.030962761
B33: 45839 | C33: 4264.32 | D33: =IFERROR(C33/C32-1,"") -> -0.019241119 | E33: 24768.35 | F33: =IFERROR(E33/E32-1,"") -> -0.029341166
B34: 45870 | C34: 4427 | D34: =IFERROR(C34/C33-1,"") -> 0.038149107 | E34: 24426.85 | F34: =IFERROR(E34/E33-1,"") -> -0.013787757
B35: 45901 | C35: 4177.88 | D35: =IFERROR(C35/C34-1,"") -> -0.056272871 | E35: 24611.1 | F35: =IFERROR(E35/E34-1,"") -> 0.0075429292
B36: 45931 | C36: 3774.81 | D36: =IFERROR(C36/C35-1,"") -> -0.096477161 | E36: 25722.1 | F36: =IFERROR(E36/E35-1,"") -> 0.045142233
... B47: 46266 | C47: 3434 | D47: =IFERROR(C47/C46-1,"") -> -0.035122225 | E47: 23063.1 | F47: =IFERROR(E47/E46-1,"") -> -0.042245976

Sheet Asian
B2: ASIAN PAINTS LTD — BETA SUPPORT
B4: Peer beta input sheet | refresh market series before interview use
B6: BETA INPUT / TRIANGULATION
B8: Company | C8: ASIAN PAINTS LTD
B9: Reference Levered Beta | C9: =J23 -> 1.1765929
B10: Method | C10: 2-year monthly regression beta vs NIFTY 50 (Oct-2024 to Sep-2026), Adj Close, Source: Yahoo Finance
B12: Raw Beta Weight | C12: 0.75
B13: Market Beta | C13: 1
B14: Market Beta Weight | C14: =1-C12 -> 0.25
B15: Adjusted Beta | C15: =C9*C12+C13*C14 -> 1.1324446
B18: Beta regression completed using 24 months of Adj Close data (Oct-2024 to Sep-2026) for the peer and NIFTY 50, sourced from Yahoo Finance. Regression Beta (J23) feeds directly into Reference Levered Beta (C9) above, which is then Blume-adjusted (rows 12-15) before use in the WACC build.
B23: Date | C23: Peer Price (Adj Close) | D23: Peer Return | E23: NIFTY Price (Adj Close) | F23: NIFTY Return | I23: Regression Beta | J23: =IFERROR(SLOPE(D25:D47,F25:F47),"") -> 1.1765929
B24: 45566 | C24: 2874.37 | E24: 24205.35
B25: 45597 | C25: 2432 | D25: =IFERROR(C25/C24-1,"") -> -0.15390155 | E25: 24131.1 | F25: =IFERROR(E25/E24-1,"") -> -0.0030675037
B26: 45627 | C26: 2237.56 | D26: =IFERROR(C26/C25-1,"") -> -0.079950658 | E26: 23644.8 | F26: =IFERROR(E26/E25-1,"") -> -0.020152417
B27: 45658 | C27: 2256.64 | D27: =IFERROR(C27/C26-1,"") -> 0.0085271456 | E27: 23508.4 | F27: =IFERROR(E27/E26-1,"") -> -0.0057687102
B28: 45689 | C28: 2137.91 | D28: =IFERROR(C28/C27-1,"") -> -0.05261362 | E28: 22124.7 | F28: =IFERROR(E28/E27-1,"") -> -0.058859812
B29: 45717 | C29: 2295.72 | D29: =IFERROR(C29/C28-1,"") -> 0.073815081 | E29: 23519.35 | F29: =IFERROR(E29/E28-1,"") -> 0.063035883
B30: 45748 | C30: 2379.14 | D30: =IFERROR(C30/C29-1,"") -> 0.036337184 | E30: 24334.2 | F30: =IFERROR(E30/E29-1,"") -> 0.03464594
B31: 45778 | C31: 2215.74 | D31: =IFERROR(C31/C30-1,"") -> -0.068680279 | E31: 24750.7 | F31: =IFERROR(E31/E30-1,"") -> 0.017115829
B32: 45809 | C32: 2317.35 | D32: =IFERROR(C32/C31-1,"") -> 0.045858269 | E32: 25517.05 | F32: =IFERROR(E32/E31-1,"") -> 0.030962761
B33: 45839 | C33: 2371.79 | D33: =IFERROR(C33/C32-1,"") -> 0.023492351 | E33: 24768.35 | F33: =IFERROR(E33/E32-1,"") -> -0.029341166
B34: 45870 | C34: 2493.05 | D34: =IFERROR(C34/C33-1,"") -> 0.051125943 | E34: 24426.85 | F34: =IFERROR(E34/E33-1,"") -> -0.013787757
B35: 45901 | C35: 2326.16 | D35: =IFERROR(C35/C34-1,"") -> -0.066942099 | E35: 24611.1 | F35: =IFERROR(E35/E34-1,"") -> 0.0075429292
B36: 45931 | C36: 2485.32 | D36: =IFERROR(C36/C35-1,"") -> 0.068421777 | E36: 25722.1 | F36: =IFERROR(E36/E35-1,"") -> 0.045142233
... B47: 46266 | C47: 2392.7 | D47: =IFERROR(C47/C46-1,"") -> -0.098319264 | E47: 23063.1 | F47: =IFERROR(E47/E46-1,"") -> -0.042245976

Sheet Berger
B2: BERGER PAINTS INDIA LTD — BETA SUPPORT
B4: Peer beta input sheet | refresh market series before interview use
B6: BETA INPUT / TRIANGULATION
B8: Company | C8: BERGER PAINTS INDIA LTD
B9: Reference Levered Beta | C9: =J23 -> 1.1857953
B10: Method | C10: 2-year monthly regression beta vs NIFTY 50 (Oct-2024 to Sep-2026), Adj Close, Source: Yahoo Finance
B12: Raw Beta Weight | C12: 0.75
B13: Market Beta | C13: 1
B14: Market Beta Weight | C14: =1-C12 -> 0.25
B15: Adjusted Beta | C15: =C9*C12+C13*C14 -> 1.1393464
B18: Beta regression completed using 24 months of Adj Close data (Oct-2024 to Sep-2026) for the peer and NIFTY 50, sourced from Yahoo Finance. Regression Beta (J23) feeds directly into Reference Levered Beta (C9) above, which is then Blume-adjusted (rows 12-15) before use in the WACC build.
B23: Date | C23: Peer Price (Adj Close) | D23: Peer Return | E23: NIFTY Price (Adj Close) | F23: NIFTY Return | I23: Regression Beta | J23: =IFERROR(SLOPE(D25:D47,F25:F47),"") -> 1.1857953
B24: 45566 | C24: 529.23 | E24: 24205.35
B25: 45597 | C25: 486.73 | D25: =IFERROR(C25/C24-1,"") -> -0.080305349 | E25: 24131.1 | F25: =IFERROR(E25/E24-1,"") -> -0.0030675037
B26: 45627 | C26: 442.22 | D26: =IFERROR(C26/C25-1,"") -> -0.091447003 | E26: 23644.8 | F26: =IFERROR(E26/E25-1,"") -> -0.020152417
B27: 45658 | C27: 466.08 | D27: =IFERROR(C27/C26-1,"") -> 0.053955045 | E27: 23508.4 | F27: =IFERROR(E27/E26-1,"") -> -0.0057687102
B28: 45689 | C28: 481.66 | D28: =IFERROR(C28/C27-1,"") -> 0.033427738 | E28: 22124.7 | F28: =IFERROR(E28/E27-1,"") -> -0.058859812
B29: 45717 | C29: 493.14 | D29: =IFERROR(C29/C28-1,"") -> 0.02383424 | E29: 23519.35 | F29: =IFERROR(E29/E28-1,"") -> 0.063035883
B30: 45748 | C30: 536.52 | D30: =IFERROR(C30/C29-1,"") -> 0.087966906 | E30: 24334.2 | F30: =IFERROR(E30/E29-1,"") -> 0.03464594
B31: 45778 | C31: 560.28 | D31: =IFERROR(C31/C30-1,"") -> 0.044285395 | E31: 24750.7 | F31: =IFERROR(E31/E30-1,"") -> 0.017115829
B32: 45809 | C32: 584.29 | D32: =IFERROR(C32/C31-1,"") -> 0.042853573 | E32: 25517.05 | F32: =IFERROR(E32/E31-1,"") -> 0.030962761
B33: 45839 | C33: 556.93 | D33: =IFERROR(C33/C32-1,"") -> -0.046826062 | E33: 24768.35 | F33: =IFERROR(E33/E32-1,"") -> -0.029341166
B34: 45870 | C34: 529.01 | D34: =IFERROR(C34/C33-1,"") -> -0.050131973 | E34: 24426.85 | F34: =IFERROR(E34/E33-1,"") -> -0.013787757
B35: 45901 | C35: 511.34 | D35: =IFERROR(C35/C34-1,"") -> -0.033402015 | E35: 24611.1 | F35: =IFERROR(E35/E34-1,"") -> 0.0075429292
B36: 45931 | C36: 538.04 | D36: =IFERROR(C36/C35-1,"") -> 0.052215747 | E36: 25722.1 | F36: =IFERROR(E36/E35-1,"") -> 0.045142233
... B47: 46266 | C47: 449.4 | D47: =IFERROR(C47/C46-1,"") -> -0.097137117 | E47: 23063.1 | F47: =IFERROR(E47/E46-1,"") -> -0.042245976

Sheet Kansai
B2: KANSAI NEROLAC PAINTS LTD — BETA SUPPORT
B4: Peer beta input sheet | refresh market series before interview use
B6: BETA INPUT / TRIANGULATION
B8: Company | C8: KANSAI NEROLAC PAINTS LTD
B9: Reference Levered Beta | C9: =J23 -> 1.2090224
B10: Method | C10: 2-year monthly regression beta vs NIFTY 50 (Oct-2024 to Sep-2026), Adj Close, Source: Yahoo Finance
B12: Raw Beta Weight | C12: 0.75
B13: Market Beta | C13: 1
B14: Market Beta Weight | C14: =1-C12 -> 0.25
B15: Adjusted Beta | C15: =C9*C12+C13*C14 -> 1.1567668
B18: Beta regression completed using 24 months of Adj Close data (Oct-2024 to Sep-2026) for the peer and NIFTY 50, sourced from Yahoo Finance. Regression Beta (J23) feeds directly into Reference Levered Beta (C9) above, which is then Blume-adjusted (rows 12-15) before use in the WACC build.
B23: Date | C23: Peer Price (Adj Close) | D23: Peer Return | E23: NIFTY Price (Adj Close) | F23: NIFTY Return | I23: Regression Beta | J23: =IFERROR(SLOPE(D25:D47,F25:F47),"") -> 1.2090224
B24: 45566 | C24: 277.34 | E24: 24205.35
B25: 45597 | C25: 273.3 | D25: =IFERROR(C25/C24-1,"") -> -0.014566958 | E25: 24131.1 | F25: =IFERROR(E25/E24-1,"") -> -0.0030675037
B26: 45627 | C26: 257.79 | D26: =IFERROR(C26/C25-1,"") -> -0.056750823 | E26: 23644.8 | F26: =IFERROR(E26/E25-1,"") -> -0.020152417
B27: 45658 | C27: 226.75 | D27: =IFERROR(C27/C26-1,"") -> -0.12040808 | E27: 23508.4 | F27: =IFERROR(E27/E26-1,"") -> -0.0057687102
B28: 45689 | C28: 220.49 | D28: =IFERROR(C28/C27-1,"") -> -0.027607497 | E28: 22124.7 | F28: =IFERROR(E28/E27-1,"") -> -0.058859812
B29: 45717 | C29: 226.56 | D29: =IFERROR(C29/C28-1,"") -> 0.027529593 | E29: 23519.35 | F29: =IFERROR(E29/E28-1,"") -> 0.063035883
B30: 45748 | C30: 250.17 | D30: =IFERROR(C30/C29-1,"") -> 0.10421081 | E30: 24334.2 | F30: =IFERROR(E30/E29-1,"") -> 0.03464594
B31: 45778 | C31: 246.79 | D31: =IFERROR(C31/C30-1,"") -> -0.013510813 | E31: 24750.7 | F31: =IFERROR(E31/E30-1,"") -> 0.017115829
B32: 45809 | C32: 249.18 | D32: =IFERROR(C32/C31-1,"") -> 0.009684347 | E32: 25517.05 | F32: =IFERROR(E32/E31-1,"") -> 0.030962761
B33: 45839 | C33: 242.02 | D33: =IFERROR(C33/C32-1,"") -> -0.028734248 | E33: 24768.35 | F33: =IFERROR(E33/E32-1,"") -> -0.029341166
B34: 45870 | C34: 237.17 | D34: =IFERROR(C34/C33-1,"") -> -0.020039666 | E34: 24426.85 | F34: =IFERROR(E34/E33-1,"") -> -0.013787757
B35: 45901 | C35: 244.47 | D35: =IFERROR(C35/C34-1,"") -> 0.03077961 | E35: 24611.1 | F35: =IFERROR(E35/E34-1,"") -> 0.0075429292
B36: 45931 | C36: 245.04 | D36: =IFERROR(C36/C35-1,"") -> 0.0023315744 | E36: 25722.1 | F36: =IFERROR(E36/E35-1,"") -> 0.045142233
... B47: 46266 | C47: 179.41 | D47: =IFERROR(C47/C46-1,"") -> -0.06949847 | E47: 23063.1 | F47: =IFERROR(E47/E46-1,"") -> -0.042245976

Sheet Rm
B2: MARKET RETURN / ERP SUPPORT
B4: Long-run market return support for CAPM
B7: ILLUSTRATIVE MARKET RETURN SERIES
B9: Year | C9: Annual Market Return | E9: Average Return | F9: =AVERAGE(C10:C34) -> 0.10832
B10: 2000 | C10: -0.1465 | E10: Dividend Yield | F10: 0.0129
B11: 2001 | C11: -0.1618 | E11: Total Market Return | F11: =SUM(F9:F10) -> 0.12122
B12: 2002 | C12: 0.0325
B13: 2003 | C13: 0.719
B14: 2004 | C14: 0.1088
B15: 2005 | C15: -0.081
B16: 2006 | C16: -0.246
B17: 2007 | C17: -0.056
B18: 2008 | C18: 0.178
B19: 2009 | C19: 0.166
B20: 2010 | C20: 0.154
B21: 2011 | C21: 0.012
B22: 2012 | C22: 0.288
B23: 2013 | C23: 0.149
... B34: 2024 | C34: 0.095

Sheet Sources
B2: SOURCES & MODEL NOTES
B5: Item | C5: Source / Reference | D5: Use in Model
B6: Pidilite FY25-26 Annual Report | C6: https://annual-reports.pidilite.com/Annual-Report-2025-26/index.html | D6: FY26 audited operating and financial context
B7: Pidilite 10-Year Financial Performance | C7: https://annual-reports.pidilite.com/Annual-Report-2025-26/10-years-financial-performance.html | D7: Historical operating results, capex and ratios
B8: Pidilite Investor Relations | C8: https://www.pidilite.com/investor-relations/ | D8: Audited results and investor materials
B9: FY26 Consolidated Results | C9: FY26 audited results / exchange filing; revenue ₹14,600.83 Cr, PBT ₹3,320.17 Cr, PAT ₹2,448.92 Cr | D9: DCF base year
B10: Market Price | C10: Public market data; 25-Sep-2026 close ₹1,517.20 | D10: Current share price
B11: India 10Y Government Bond | C11: Public market data; 25-Sep-2026 yield ~7.12% | D11: Risk-free rate
B12: Peer Betas (regression) | C12: Yahoo Finance monthly Adj Close, Oct-2024 to Sep-2026: ASTRAL.NS, SUPREMEIND.NS, ASIANPAINT.NS, BERGEPAINT.NS, KANSAINER.NS, ^NSEI | D12: Regression beta (SLOPE of peer vs NIFTY monthly returns) -> Blume-adjusted -> unlevered/relevered in WACC
B13: DCF Convention | C13: Mid-year discounting; 10-year explicit FCFF then Gordon Growth terminal value | D13: Valuation methodology
B14: Peer LTM financials | C14: screener.in consolidated TTM to Jun-2026 (EBITDA, PAT, EPS, investments); pulled 28-Sep-2026 | D14: Trading comps (Comps tab)
B15: Peer market caps | C15: Sep-2026 close (Yahoo Finance) x shares outstanding (Cr): Asian 95.77, Berger 116.57, Kansai 80.71, Astral 26.9, Supreme 12.70 | D15: Peer equity value for D/E and EV multiples
B16: Key model conventions
B17: 1. Consolidated financials are used for enterprise-value DCF consistency. 2. Forecasts run FY27E–FY36E (10-year fade: growth 11% to 6%, EBITDA margin 27.5% to 26.0%). 3. FCFF = EBIT × (1-tax) + D&A – Capex – Change in Operating NWC. 4. Terminal value uses Gordon Growth; TV discounted with the final-year mid-year factor. 5. Sensitivity table is centred on the live base-case WACC and terminal growth. 6. Reverse DCF estimates the terminal growth required to reconcile the market price. 7. Yellow cells are inputs; green cells are key outputs. 8. Cross-check: trading comps (EV/EBITDA, P/E) on the Comps tab; DCF vs comps spread on DCF!N60.
